<mujoco model="UF_ROBOT">
  <option iterations="50" timestep="0.001" solver="PGS" gravity="0 0 -9.81" />

  <compiler angle="radian" eulerseq="zyx" autolimits="true" />

  <default>
    <joint limited="true" damping="0.01" armature="0.01" frictionloss="0.01" />
    <geom condim="4" contype="1" conaffinity="15" friction="0.9 0.2 0.2" solref="0.001 2" />
    <motor ctrllimited="true" />
    <equality solref="0.001 2" />
    <default class="visualgeom">
      <geom material="visualgeom" condim="1" contype="0" conaffinity="0" />
    </default>
  </default>

  <asset>
    <mesh name="link_base" content_type="model/stl" file="link_base.stl" />
    <mesh name="link1" content_type="model/stl" file="link1.stl" />
    <mesh name="link2" content_type="model/stl" file="link2.stl" />
    <mesh name="link3" content_type="model/stl" file="link3.stl" />
    <mesh name="link4" content_type="model/stl" file="link4.stl" />
    <mesh name="link5" content_type="model/stl" file="link5.stl" />
    <mesh name="link6" content_type="model/stl" file="link6.stl" />
    <mesh name="end_tool" content_type="model/stl" file="end_tool.stl" />
    <mesh name="base_link" content_type="model/stl" file="base_link.stl" />
    <mesh name="left_outer_knuckle" content_type="model/stl" file="left_outer_knuckle.stl" />
    <mesh name="left_finger" content_type="model/stl" file="left_finger.stl" />
    <mesh name="left_inner_knuckle" content_type="model/stl" file="left_inner_knuckle.stl" />
    <mesh name="right_outer_knuckle" content_type="model/stl" file="right_outer_knuckle.stl" />
    <mesh name="right_finger" content_type="model/stl" file="right_finger.stl" />
    <mesh name="right_inner_knuckle" content_type="model/stl" file="right_inner_knuckle.stl" />
    <texture name="texplane" type="2d" builtin="checker" rgb1=".0 .0 .0" rgb2=".8 .8 .8" width="100" height="100" />
    <material name="matplane" reflectance="0." texture="texplane" texrepeat="1 1" texuniform="true" />
    <material name="visualgeom" rgba="0.5 0.9 0.2 1" />
  </asset>

  <worldbody>
    <!-- <light directional="true" diffuse="0.4 0.4 0.4" specular="0.1 0.1 0.1" pos="0 0 5.0" dir="0 0 -1" castshadow="false" />
    <light directional="true" diffuse="0.6 0.6 0.6" specular="0.2 0.2 0.2" pos="0 0 4" dir="0 0 -1" />
    <geom name="ground" type="plane" pos="0 0 0" size="100 100 0.001" quat="1 0 0 0" material="matplane" condim="3" conaffinity="15" />
    <camera name="fixed" pos="0 -3.0 0.4263968685789247" xyaxes="1 0 0 0 0 1" />
    <camera name="track" mode="trackcom" pos="0 -3.0 0.4263968685789247" xyaxes="1 0 0 0 0 1" /> -->
    <body name="root" pos="0 0 -0.07360313142107527" quat="1 0 0 0">
      <freejoint name="root" />
      <site name="imu" size="0.01" pos="0 0 0" />
      <geom pos="0 0 0.12" quat="1 0 0 0" type="mesh" rgba="1 1 1 1" mesh="link_base" contype="1" conaffinity="0" density="0" group="1" class="visualgeom" />
      <geom type="mesh" rgba="1 1 1 1" mesh="link_base" pos="0 0 0.12" quat="1 0 0 0" />
      <body name="link1" pos="0 0 0.387">
        <inertial pos="-0.0002 0.02905 -0.01233" quat="0.978953 -0.202769 -0.00441617 -0.0227264" mass="2.382" diaginertia="0.00569127 0.00533384 0.00293865" />
        <joint name="joint1" pos="0 0 0" axis="0 0 1" range="-6.28319 6.28319" actuatorfrcrange="-50 50" damping="10" frictionloss="1" />
        <geom type="mesh" rgba="1 1 1 1" mesh="link1" contype="1" conaffinity="0" density="0" group="1" class="visualgeom" />
        <geom type="mesh" rgba="1 1 1 1" mesh="link1" />
        <body name="link2" quat="0.707105 -0.707108 0 0">
          <inertial pos="0.00022 -0.12856 0.01735" quat="0.50198 0.86483 -0.00778841 0.00483285" mass="1.869" diaginertia="0.00959898 0.00937717 0.00201315" />
          <joint name="joint2" pos="0 0 0" axis="0 0 1" range="-2.059 2.0944" actuatorfrcrange="-50 50" damping="10" frictionloss="1" />
          <geom type="mesh" rgba="1 1 1 1" mesh="link2" contype="1" conaffinity="0" density="0" group="1" class="visualgeom" />
          <geom type="mesh" rgba="1 1 1 1" mesh="link2" />
          <body name="link3" pos="0 -0.293 0" quat="0.707105 0.707108 0 0">
            <inertial pos="0.0466 -0.02463 -0.00768" quat="0.913819 0.289775 0.281481 -0.0416455" mass="1.6383" diaginertia="0.00351721 0.00294089 0.00195868" />
            <joint name="joint3" pos="0 0 0" axis="0 0 1" range="-6.28319 6.28319" actuatorfrcrange="-30 30" damping="5" frictionloss="1" />
            <geom type="mesh" rgba="1 1 1 1" mesh="link3" contype="1" conaffinity="0" density="0" group="1" class="visualgeom" />
            <geom type="mesh" rgba="1 1 1 1" mesh="link3" />
            <body name="link4" pos="0.0525 0 0" quat="0.707105 0.707108 0 0">
              <inertial pos="0.07047 -0.11575 0.012" quat="0.422108 0.852026 -0.126025 0.282832" mass="1.7269" diaginertia="0.00657137 0.00647948 0.00186763" />
              <joint name="joint4" pos="0 0 0" axis="0 0 1" range="-0.19198 3.927" actuatorfrcrange="-30 30" damping="5" frictionloss="1" />
              <geom type="mesh" rgba="1 1 1 1" mesh="link4" contype="1" conaffinity="0" density="0" group="1" class="visualgeom" />
              <geom type="mesh" rgba="1 1 1 1" mesh="link4" />
              <body name="link5" pos="0.0775 -0.3425 0" quat="0.707105 0.707108 0 0">
                <inertial pos="-0.00032 0.01604 -0.026" quat="0.999311 -0.0304457 0.000577067 0.0212082" mass="1.3203" diaginertia="0.00534729 0.00499076 0.0013489" />
                <joint name="joint5" pos="0 0 0" axis="0 0 1" range="-6.28319 6.28319" actuatorfrcrange="-30 30" damping="5" frictionloss="1" />
                <geom type="mesh" rgba="1 1 1 1" mesh="link5" contype="1" conaffinity="0" density="0" group="1" class="visualgeom" />
                <geom type="mesh" rgba="1 1 1 1" mesh="link5" />
                <body name="link6" quat="0.707105 0.707108 0 0">
                  <inertial pos="0.06469 0.03278 0.02141" quat="-0.217672 0.772419 0.16258 0.574069" mass="1.325" diaginertia="0.00245421 0.00221646 0.00107273" />
                  <joint name="joint6" pos="0 0 0" axis="0 0 1" range="-1.69297 3.14159" actuatorfrcrange="-20 20" damping="2" frictionloss="1" />
                  <geom type="mesh" rgba="1 1 1 1" mesh="link6" contype="1" conaffinity="0" density="0" group="1" class="visualgeom" />
                  <geom type="mesh" rgba="1 1 1 1" mesh="link6" />
                  <body name="link7" pos="0.076 0.097 0" quat="0.707105 -0.707108 0 0">
                    <inertial pos="-0.000498429 -0.00302522 0.0339303" quat="0.99835 -0.0570933 -0.00608801 0.000149964" mass="0.71156" diaginertia="0.0010178 0.00084597 0.000385531" />
                    <joint name="joint7" pos="0 0 0" axis="0 0 1" range="-6.28319 6.28319" actuatorfrcrange="-20 20" damping="2" frictionloss="1" />
                    <geom type="mesh" rgba="0.753 0.753 0.753 1" mesh="end_tool" contype="1" conaffinity="0" density="0" group="1" class="visualgeom" />
                    <geom type="mesh" rgba="0.753 0.753 0.753 1" mesh="end_tool" />
                    <geom quat="0 0 0 1" type="mesh" rgba="1 1 1 1" mesh="base_link" contype="1" conaffinity="0" density="0" group="1" class="visualgeom" />
                    <geom type="mesh" rgba="1 1 1 1" mesh="base_link" quat="0 0 0 1" />
                    <body name="left_outer_knuckle" pos="0 -0.035 0.059098" quat="0 0 0 1">
                      <inertial pos="0 0.021559 0.015181" quat="0.47789 0.87842 0 0" mass="0.033618" diaginertia="1.9111e-05 1.79089e-05 1.90167e-06" />
                      <joint name="drive_joint" pos="0 0 0" axis="1 0 0" range="0 0.85" actuatorfrcrange="-50 50" />
                      <geom type="mesh" rgba="0.753 0.753 0.753 1" mesh="left_outer_knuckle" contype="1" conaffinity="0" density="0" group="1" class="visualgeom" />
                      <geom type="mesh" rgba="0.753 0.753 0.753 1" mesh="left_outer_knuckle" />
                      <body name="left_finger" pos="0 0.035465 0.042039">
                        <inertial pos="0 -0.016413 0.029258" quat="0.697634 0.115353 -0.115353 0.697634" mass="0.048304" diaginertia="1.88037e-05 1.7493e-05 3.56792e-06" />
                        <joint name="left_finger_joint" pos="0 0 0" axis="-1 0 0" range="0 0.85" actuatorfrcrange="-50 50" />
                        <geom type="mesh" rgba="0.753 0.753 0.753 1" mesh="left_finger" contype="1" conaffinity="0" density="0" group="1" class="visualgeom" />
                        <geom type="mesh" rgba="0.753 0.753 0.753 1" mesh="left_finger" />
                      </body>
                    </body>
                    <body name="left_inner_knuckle" pos="0 -0.02 0.074098" quat="0 0 0 1">
                      <inertial pos="1.86601e-06 0.0220468 0.0261335" quat="0.664139 -0.242732 0.242713 0.664146" mass="0.0230126" diaginertia="8.34216e-06 6.0949e-06 2.75601e-06" />
                      <joint name="left_inner_knuckle_joint" pos="0 0 0" axis="1 0 0" range="0 0.85" actuatorfrcrange="-50 50" />
                      <geom type="mesh" rgba="0.753 0.753 0.753 1" mesh="left_inner_knuckle" contype="1" conaffinity="0" density="0" group="1" class="visualgeom" />
                      <geom type="mesh" rgba="0.753 0.753 0.753 1" mesh="left_inner_knuckle" />
                    </body>
                    <body name="right_outer_knuckle" pos="0 0.035 0.059098" quat="0 0 0 1">
                      <inertial pos="0 -0.021559 0.015181" quat="0.87842 0.47789 0 0" mass="0.033618" diaginertia="1.9111e-05 1.79089e-05 1.90167e-06" />
                      <joint name="right_outer_knuckle_joint" pos="0 0 0" axis="-1 0 0" range="0 0.85" actuatorfrcrange="-50 50" />
                      <geom type="mesh" rgba="0.753 0.753 0.753 1" mesh="right_outer_knuckle" contype="1" conaffinity="0" density="0" group="1" class="visualgeom" />
                      <geom type="mesh" rgba="0.753 0.753 0.753 1" mesh="right_outer_knuckle" />
                      <body name="right_finger" pos="0 -0.035465 0.042039">
                        <inertial pos="0 0.016413 0.029258" quat="0.697634 -0.115356 0.115356 0.697634" mass="0.048304" diaginertia="1.88038e-05 1.7493e-05 3.56779e-06" />
                        <joint name="right_finger_joint" pos="0 0 0" axis="1 0 0" range="0 0.85" actuatorfrcrange="-50 50" />
                        <geom type="mesh" rgba="0.753 0.753 0.753 1" mesh="right_finger" contype="1" conaffinity="0" density="0" group="1" class="visualgeom" />
                        <geom type="mesh" rgba="0.753 0.753 0.753 1" mesh="right_finger" />
                      </body>
                    </body>
                    <body name="right_inner_knuckle" pos="0 0.02 0.074098" quat="0 0 0 1">
                      <inertial pos="1.866e-06 -0.022047 0.026133" quat="0.66415 0.242702 -0.242721 0.664144" mass="0.023013" diaginertia="8.34209e-06 6.0949e-06 2.75601e-06" />
                      <joint name="right_inner_knuckle_joint" pos="0 0 0" axis="-1 0 0" range="0 0.85" actuatorfrcrange="-50 50" />
                      <geom type="mesh" rgba="0.753 0.753 0.753 1" mesh="right_inner_knuckle" contype="1" conaffinity="0" density="0" group="1" class="visualgeom" />
                      <geom type="mesh" rgba="0.753 0.753 0.753 1" mesh="right_inner_knuckle" />
                    </body>
                  </body>
                </body>
              </body>
            </body>
          </body>
        </body>
      </body>
    </body>
  </worldbody>

  <actuator>
    <motor name="joint1" joint="joint1" ctrllimited="true" ctrlrange="-50 50" gear="1" />
    <motor name="joint2" joint="joint2" ctrllimited="true" ctrlrange="-50 50" gear="1" />
    <motor name="joint3" joint="joint3" ctrllimited="true" ctrlrange="-30 30" gear="1" />
    <motor name="joint4" joint="joint4" ctrllimited="true" ctrlrange="-30 30" gear="1" />
    <motor name="joint5" joint="joint5" ctrllimited="true" ctrlrange="-30 30" gear="1" />
    <motor name="joint6" joint="joint6" ctrllimited="true" ctrlrange="-20 20" gear="1" />
    <motor name="joint7" joint="joint7" ctrllimited="true" ctrlrange="-20 20" gear="1" />
    <motor name="drive_joint" joint="drive_joint" ctrllimited="true" ctrlrange="-50 50" gear="1" />
    <motor name="left_finger_joint" joint="left_finger_joint" ctrllimited="true" ctrlrange="-50 50" gear="1" />
    <motor name="left_inner_knuckle_joint" joint="left_inner_knuckle_joint" ctrllimited="true" ctrlrange="-50 50" gear="1" />
    <motor name="right_outer_knuckle_joint" joint="right_outer_knuckle_joint" ctrllimited="true" ctrlrange="-50 50" gear="1" />
    <motor name="right_finger_joint" joint="right_finger_joint" ctrllimited="true" ctrlrange="-50 50" gear="1" />
    <motor name="right_inner_knuckle_joint" joint="right_inner_knuckle_joint" ctrllimited="true" ctrlrange="-50 50" gear="1" />
  </actuator>

  <sensor>
    <actuatorpos name="joint1_p" actuator="joint1" />
    <actuatorvel name="joint1_v" actuator="joint1" />
    <actuatorfrc name="joint1_f" actuator="joint1" noise="0.001" />
    <actuatorpos name="joint2_p" actuator="joint2" />
    <actuatorvel name="joint2_v" actuator="joint2" />
    <actuatorfrc name="joint2_f" actuator="joint2" noise="0.001" />
    <actuatorpos name="joint3_p" actuator="joint3" />
    <actuatorvel name="joint3_v" actuator="joint3" />
    <actuatorfrc name="joint3_f" actuator="joint3" noise="0.001" />
    <actuatorpos name="joint4_p" actuator="joint4" />
    <actuatorvel name="joint4_v" actuator="joint4" />
    <actuatorfrc name="joint4_f" actuator="joint4" noise="0.001" />
    <actuatorpos name="joint5_p" actuator="joint5" />
    <actuatorvel name="joint5_v" actuator="joint5" />
    <actuatorfrc name="joint5_f" actuator="joint5" noise="0.001" />
    <actuatorpos name="joint6_p" actuator="joint6" />
    <actuatorvel name="joint6_v" actuator="joint6" />
    <actuatorfrc name="joint6_f" actuator="joint6" noise="0.001" />
    <actuatorpos name="joint7_p" actuator="joint7" />
    <actuatorvel name="joint7_v" actuator="joint7" />
    <actuatorfrc name="joint7_f" actuator="joint7" noise="0.001" />
    <actuatorpos name="drive_joint_p" actuator="drive_joint" />
    <actuatorvel name="drive_joint_v" actuator="drive_joint" />
    <actuatorfrc name="drive_joint_f" actuator="drive_joint" noise="0.001" />
    <actuatorpos name="left_finger_joint_p" actuator="left_finger_joint" />
    <actuatorvel name="left_finger_joint_v" actuator="left_finger_joint" />
    <actuatorfrc name="left_finger_joint_f" actuator="left_finger_joint" noise="0.001" />
    <actuatorpos name="left_inner_knuckle_joint_p" actuator="left_inner_knuckle_joint" />
    <actuatorvel name="left_inner_knuckle_joint_v" actuator="left_inner_knuckle_joint" />
    <actuatorfrc name="left_inner_knuckle_joint_f" actuator="left_inner_knuckle_joint" noise="0.001" />
    <actuatorpos name="right_outer_knuckle_joint_p" actuator="right_outer_knuckle_joint" />
    <actuatorvel name="right_outer_knuckle_joint_v" actuator="right_outer_knuckle_joint" />
    <actuatorfrc name="right_outer_knuckle_joint_f" actuator="right_outer_knuckle_joint" noise="0.001" />
    <actuatorpos name="right_finger_joint_p" actuator="right_finger_joint" />
    <actuatorvel name="right_finger_joint_v" actuator="right_finger_joint" />
    <actuatorfrc name="right_finger_joint_f" actuator="right_finger_joint" noise="0.001" />
    <actuatorpos name="right_inner_knuckle_joint_p" actuator="right_inner_knuckle_joint" />
    <actuatorvel name="right_inner_knuckle_joint_v" actuator="right_inner_knuckle_joint" />
    <actuatorfrc name="right_inner_knuckle_joint_f" actuator="right_inner_knuckle_joint" noise="0.001" />
    <framequat name="orientation" objtype="site" noise="0.001" objname="imu" />
    <gyro name="angular-velocity" site="imu" noise="0.005" cutoff="34.9" />
  </sensor>
</mujoco>